Workbook

Sheet выдержка
A1: Подрядчик T&M | B1: Было | C1: Сумма изменений | D1: Стало без овертаймов | E1: Овертаймы | F1: Стало с овертаймами
A2: Вакансия 670. Senior разработчик БД | B2: ='670. Senior разработчик БД'!C48 -> 0 | C2: ='670. Senior разработчик БД'!D48 -> 2576968.6 | D2: ='670. Senior разработчик БД'!E48 -> 2454255.8 | E2: ='670. Senior разработчик БД'!F48 -> 122712.79 | F2: ='670. Senior разработчик БД'!G48 -> 2576968.6
A3: Итого: | B3: =B2 -> 0 | C3: =C2 -> 2576968.6 | D3: =D2 -> 2454255.8 | E3: =E2 -> 122712.79 | F3: =F2 -> 2576968.6

Sheet 670. Senior разработчик БД
A1: Месяц | B1: 11.2024 | C1: 12.2024 | D1: 01.2025 | E1: 02.2025 | F1: 03.2025 | G1: 04.2025 | H1: 05.2025 | I1: 06.2025 | J1: 07.2025 | K1: 08.2025 | L1: 09.2025 | M1: 10.2025 | N1: 11.2025 | O1: 12.2025
A2: Норма часов | B2: 167 | C2: 168 | D2: 136 | E2: 160 | F2: 167 | G2: 175 | H2: 144 | I2: 151 | J2: 184 | K2: 168 | L2: 176 | M2: 184 | N2: 151 | O2: 176
A3: Месяц выполнения работ | B3: Специалист | C3: Роль | D3: Загрузка по респлану | E3: Часы ПЛАН | F3: Часы ФАКТ | G3: Ставка | H3: Итого без овертаймов | I3: Заложено в ФП | J3: Сумма изменений | K3: 5% овертаймы | L3: Итого с овертаймами | M3: Комментарий
A4: 45597 | B4: Вакансия 670. Senior разработчик БД | C4: Senior разработчик БД | D4: 0.5 | E4: =D4*B2 -> 83.5 | G4: 2127.66 | H4: =E4*G4 -> 177659.61
B5: ИТОГО Ноябрь 24 | H5: =SUM(H4:H4) -> 177659.61 | I5: 0 | J5: =L5-I5 -> 186542.59 | K5: =H5*5% -> 8882.9805 | L5: =H5+K5 -> 186542.59
A6: 45627 | B6: Вакансия 670. Senior разработчик БД | C6: Senior разработчик БД | D6: 0.5 | E6: =D6*C2 -> 84 | G6: 2127.66 | H6: =E6*G6 -> 178723.44
B7: ИТОГО Декабрь 24 | H7: =SUM(H6:H6) -> 178723.44 | I7: 0 | J7: =L7-I7 -> 187659.61 | K7: =H7*5% -> 8936.172 | L7: =H7+K7 -> 187659.61
A8: 45658 | B8: Вакансия 670. Senior разработчик БД | C8: Senior разработчик БД | D8: 0.5 | E8: =D8*D2 -> 68 | G8: 2127.66 | H8: =E8*G8 -> 144680.88
B9: ИТОГО Январь 25 | H9: =SUM(H8:H8) -> 144680.88 | I9: 0 | J9: =L9-I9 -> 151914.92 | K9: =H9*5% -> 7234.044 | L9: =H9+K9 -> 151914.92
A10: 45689 | B10: Вакансия 670. Senior разработчик БД | C10: Senior разработчик БД | D10: 0.5 | E10: =D10*E2 -> 80 | G10: 2127.66 | H10: =E10*G10 -> 170212.8
B11: ИТОГО Февраль 25 | H11: =SUM(H10:H10) -> 170212.8 | I11: 0 | J11: =L11-I11 -> 178723.44 | K11: =H11*5% -> 8510.64 | L11: =H11+K11 -> 178723.44
A12: 45717 | B12: Вакансия 670. Senior разработчик БД | C12: Senior разработчик БД | D12: 0.5 | E12: =D12*F2 -> 83.5 | G12: 2127.66 | H12: =E12*G12 -> 177659.61
B13: ИТОГО Март 25 | H13: =SUM(H12:H12) -> 177659.61 | I13: 0 | J13: =L13-I13 -> 186542.59 | K13: =H13*5% -> 8882.9805 | L13: =H13+K13 -> 186542.59
A14: 45748 | B14: Вакансия 670. Senior разработчик БД | C14: Senior разработчик БД | D14: 0.5 | E14: =D14*G2 -> 87.5 | G14: 2127.66 | H14: =E14*G14 -> 186170.25
B15: ИТОГО Апрель 25 | H15: =SUM(H14:H14) -> 186170.25 | I15: 0 | J15: =L15-I15 -> 195478.76 | K15: =H15*5% -> 9308.5125 | L15: =H15+K15 -> 195478.76
A16: 45778 | B16: Вакансия 670. Senior разработчик БД | C16: Senior разработчик БД | D16: 0.5 | E16: =D16*H2 -> 72 | G16: 2127.66 | H16: =E16*G16 -> 153191.52
B17: ИТОГО Май 25 | H17: =SUM(H16:H16) -> 153191.52 | I17: 0 | J17: =L17-I17 -> 160851.1 | K17: =H17*5% -> 7659.576 | L17: =H17+K17 -> 160851.1
A18: 45809 | B18: Вакансия 670. Senior разработчик БД | C18: Senior разработчик БД | D18: 0.5 | E18: =D18*I2 -> 75.5 | G18: 2127.66 | H18: =E18*G18 -> 160638.33
B19: ИТОГО Июнь 25 | H19: =SUM(H18:H18) -> 160638.33 | I19: 0 | J19: =L19-I19 -> 168670.25 | K19: =H19*5% -> 8031.9165 | L19: =H19+K19 -> 168670.25
A20: 45839 | B20: Вакансия 670. Senior разработчик БД | C20: Senior разработчик БД | D20: 0.5 | E20: =D20*J2 -> 92 | G20: 2127.66 | H20: =E20*G20 -> 195744.72
B21: ИТОГО Июль 25 | H21: =SUM(H20:H20) -> 195744.72 | I21: 0 | J21: =L21-I21 -> 205531.96 | K21: =H21*5% -> 9787.236 | L21: =H21+K21 -> 205531.96
A22: 45870 | B22: Вакансия 670. Senior разработчик БД | C22: Senior разработчик БД | D22: 0.5 | E22: =D22*K2 -> 84 | G22: 2127.66 | H22: =E22*G22 -> 178723.44
B23: ИТОГО Август 25 | H23: =SUM(H22:H22) -> 178723.44 | I23: 0 | J23: =L23-I23 -> 187659.61 | K23: =H23*5% -> 8936.172 | L23: =H23+K23 -> 187659.61
A24: 45901 | B24: Вакансия 670. Senior разработчик БД | C24: Senior разработчик БД | D24: 0.5 | E24: =D24*L2 -> 88 | G24: 2127.66 | H24: =E24*G24 -> 187234.08
B25: ИТОГО Сентябрь 25 | H25: =SUM(H24:H24) -> 187234.08 | I25: 0 | J25: =L25-I25 -> 196595.78 | K25: =H25*5% -> 9361.704 | L25: =H25+K25 -> 196595.78
A26: 45931 | B26: Вакансия 670. Senior разработчик БД | C26: Senior разработчик БД | D26: 0.5 | E26: =D26*M2 -> 92 | G26: 2127.66 | H26: =E26*G26 -> 195744.72
B27: ИТОГО Октябрь 25 | H27: =SUM(H26:H26) -> 195744.72 | I27: 0 | J27: =L27-I27 -> 205531.96 | K27: =H27*5% -> 9787.236 | L27: =H27+K27 -> 205531.96
A28: 45962 | B28: Вакансия 670. Senior разработчик БД | C28: Senior разработчик БД | D28: 0.5 | E28: =D28*N2 -> 75.5 | G28: 2127.66 | H28: =E28*G28 -> 160638.33
B29: ИТОГО Ноябрь 25 | H29: =SUM(H28:H28) -> 160638.33 | I29: 0 | J29: =L29-I29 -> 168670.25 | K29: =H29*5% -> 8031.9165 | L29: =H29+K29 -> 168670.25
A30: 45992 | B30: Вакансия 670. Senior разработчик БД | C30: Senior разработчик БД | D30: 0.5 | E30: =D30*O2 -> 88 | G30: 2127.66 | H30: =E30*G30 -> 187234.08
B31: ИТОГО Декабрь 25 | H31: =SUM(H30:H30) -> 187234.08 | I31: 0 | J31: =L31-I31 -> 196595.78 | K31: =H31*5% -> 9361.704 | L31: =H31+K31 -> 196595.78
A33: Месяц | B33: Подрядчик | C33: Было | D33: Сумма изменений | E33: Стало без овертаймов | F33: Овертаймы 5% | G33: Стало с овертаймами | H33: Комментарий
A34: 45597 | B34: Вакансия 670. Senior разработчик БД | C34: =I5 -> 0 | D34: =J5 -> 186542.59 | E34: =H5 -> 177659.61 | F34: =K5 -> 8882.9805 | G34: =L5 -> 186542.59
A35: 45627 | B35: Вакансия 670. Senior разработчик БД | C35: =I7 -> 0 | D35: =J7 -> 187659.61 | E35: =H7 -> 178723.44 | F35: =K7 -> 8936.172 | G35: =L7 -> 187659.61
A36: 45658 | B36: Вакансия 670. Senior разработчик БД | C36: =I9 -> 0 | D36: =J9 -> 151914.92 | E36: =H9 -> 144680.88 | F36: =K9 -> 7234.044 | G36: =L9 -> 151914.92
A37: 45689 | B37: Вакансия 670. Senior разработчик БД | C37: =I11 -> 0 | D37: =J11 -> 178723.44 | E37: =H11 -> 170212.8 | F37: =K11 -> 8510.64 | G37: =L11 -> 178723.44
A38: 45717 | B38: Вакансия 670. Senior разработчик БД | C38: =I13 -> 0 | D38: =J13 -> 186542.59 | E38: =H13 -> 177659.61 | F38: =K13 -> 8882.9805 | G38: =L13 -> 186542.59
A39: 45748 | B39: Вакансия 670. Senior разработчик БД | C39: =I15 -> 0 | D39: =J15 -> 195478.76 | E39: =H15 -> 186170.25 | F39: =K15 -> 9308.5125 | G39: =L15 -> 195478.76
A40: 45778 | B40: Вакансия 670. Senior разработчик БД | C40: =I17 -> 0 | D40: =J17 -> 160851.1 | E40: =H17 -> 153191.52 | F40: =K17 -> 7659.576 | G40: =L17 -> 160851.1
A41: 45809 | B41: Вакансия 670. Senior разработчик БД | C41: =I19 -> 0 | D41: =J19 -> 168670.25 | E41: =H19 -> 160638.33 | F41: =K19 -> 8031.9165 | G41: =L19 -> 168670.25
...
