Workbook
Name Срез_Месяц_выполнения_работ: #N/A
Name Срез_Подрядчик: #N/A
Name Срез_Специалист: #N/A

Sheet выдержка
B3: Итого_без_овертаймов | C3: Заложено_в_ФП | D3: Итого_со_страховыми | E3: Сумма_изменений
A4: ГПХ
A5: Толстоусова Ольга | B5: 926820 | C5: 997259 | D5: 997259 | E5: 0
A6: ИП
A7: Сазонов Павел | B7: 130000 | C7: 130000 | D7: 130000 | E7: 0
A8: СМЗ
A9: Захаров Юрий | B9: 1275171 | C9: 1300703 | D9: 1275171 | E9: -25532
A10: Карпов Алексей | B10: 691200 | C10: 691200 | D10: 691200 | E10: 0
A11: Черепанов Валерий | B11: 525840 | C11: 525840 | D11: 525840 | E11: 0
A12: Общий итог | B12: 3549031 | C12: 3645002 | D12: 3619470 | E12: -25532
B15: Итого_за_период без_НДС | C15: Итого_за_период _с_НДС | D15: Заложено_в_ФП_с_НДС | E15: Сумма_изменений_с_НДС
A16: МТИ
A17: 0.22 | B17: 8970462 | C17: 10943964 | D17: 10943964 | E17: 0
A18: ООО "Исходный код"
A19: 0.2 | B19: 37500000 | C19: 45000000 | D19: 0 | E19: 45000000
A20: Общий итог | B20: 46470462 | C20: 55943964 | D20: 10943964 | E20: 45000000

Sheet расчеты_T&M
A13: Месяц выполнения работ | B13: Специалист | C13: Форма контрактации | D13: Ставка НДС | E13: Роль | F13: Загрузка респлан | G13: Часы ПЛАН | H13: Часы ФАКТ | I13: Ставка Gross | J13: Итого без овертаймов | K13: Заложено в ФП | L13: Сумма изменений | M13: Страховые взносы 7,8% | N13: Итого со страховыми | O13: Прогнозный месяц подписания Акта | P13: Прогнозный срок выплат | Q13: Комментарий
A14: 45627 | B14: Захаров Юрий | C14: СМЗ | D14: 0 | E14: Senior разработчик БД | F14: 0.24 | G14: =ROUND(Таблица1[[#This Row],[Загрузка респлан]]*VLOOKUP(Таблица1[[#This Row],[Месяц выполнения работ]],технический!$A$1:$B$25,2,FALSE),0) -> 40 | H14: 40.33 | I14: 2127.66 | J14: =ROUND(I14*IF(Таблица1[[#This Row],[Часы ФАКТ]]="",Таблица1[[#This Row],[Часы ПЛАН]],Таблица1[[#This Row],[Часы ФАКТ]]),0) -> 85809 | K14: 85809 | L14: =IF(Таблица1[[#This Row],[Форма контрактации]]="ГПХ", Таблица1[[#This Row],[Итого со страховыми]]-Таблица1[[#This Row],[Заложено в ФП]], Таблица1[[#This Row],[Итого без овертаймов]]-Таблица1[[#This Row],[Заложено в ФП]]) -> 0 | M14: =IF(Таблица1[[#This Row],[Форма контрактации]]="ГПХ", Таблица1[[#This Row],[Итого без овертаймов]]*7.6%, "0") -> 0 | N14: =ROUND(Таблица1[[#This Row],[Итого без овертаймов]]+Таблица1[[#This Row],[Страховые взносы 7,8%]],0) -> 85809 | O14: 45658 | P14: 45658 | Q14: оплачено 31.01.2025
A15: 45658 | B15: Захаров Юрий | C15: СМЗ | D15: 0 | E15: Senior разработчик БД | F15: 0.22 | G15: =ROUND(Таблица1[[#This Row],[Загрузка респлан]]*VLOOKUP(Таблица1[[#This Row],[Месяц выполнения работ]],технический!$A$1:$B$25,2,FALSE),0) -> 30 | H15: 30 | I15: 2127.66 | J15: =ROUND(I15*IF(Таблица1[[#This Row],[Часы ФАКТ]]="",Таблица1[[#This Row],[Часы ПЛАН]],Таблица1[[#This Row],[Часы ФАКТ]]),0) -> 63830 | K15: 63830 | L15: =IF(Таблица1[[#This Row],[Форма контрактации]]="ГПХ", Таблица1[[#This Row],[Итого со страховыми]]-Таблица1[[#This Row],[Заложено в ФП]], Таблица1[[#This Row],[Итого без овертаймов]]-Таблица1[[#This Row],[Заложено в ФП]]) -> 0 | M15: =IF(Таблица1[[#This Row],[Форма контрактации]]="ГПХ", Таблица1[[#This Row],[Итого без овертаймов]]*7.6%, "0") -> 0 | N15: =ROUND(Таблица1[[#This Row],[Итого без овертаймов]]+Таблица1[[#This Row],[Страховые взносы 7,8%]],0) -> 63830 | O15: 45717 | P15: 45717 | Q15: оплачено в марте 2025
A16: 45689 | B16: Захаров Юрий | C16: СМЗ | D16: 0 | E16: Senior разработчик БД | F16: 0.5 | G16: =ROUND(Таблица1[[#This Row],[Загрузка респлан]]*VLOOKUP(Таблица1[[#This Row],[Месяц выполнения работ]],технический!$A$1:$B$25,2,FALSE),0) -> 80 | H16: 80 | I16: 2127.66 | J16: =ROUND(I16*IF(Таблица1[[#This Row],[Часы ФАКТ]]="",Таблица1[[#This Row],[Часы ПЛАН]],Таблица1[[#This Row],[Часы ФАКТ]]),0) -> 170213 | K16: 170213 | L16: =IF(Таблица1[[#This Row],[Форма контрактации]]="ГПХ", Таблица1[[#This Row],[Итого со страховыми]]-Таблица1[[#This Row],[Заложено в ФП]], Таблица1[[#This Row],[Итого без овертаймов]]-Таблица1[[#This Row],[Заложено в ФП]]) -> 0 | M16: =IF(Таблица1[[#This Row],[Форма контрактации]]="ГПХ", Таблица1[[#This Row],[Итого без овертаймов]]*7.6%, "0") -> 0 | N16: =ROUND(Таблица1[[#This Row],[Итого без овертаймов]]+Таблица1[[#This Row],[Страховые взносы 7,8%]],0) -> 170213 | O16: 45748 | P16: 45778 | Q16: оплачено 13.05.2025
A17: 45717 | B17: Захаров Юрий | C17: СМЗ | D17: 0 | E17: Senior разработчик БД | F17: 0.49 | G17: =ROUND(Таблица1[[#This Row],[Загрузка респлан]]*VLOOKUP(Таблица1[[#This Row],[Месяц выполнения работ]],технический!$A$1:$B$25,2,FALSE),0) -> 82 | H17: 81 | I17: 2127.66 | J17: =ROUND(I17*IF(Таблица1[[#This Row],[Часы ФАКТ]]="",Таблица1[[#This Row],[Часы ПЛАН]],Таблица1[[#This Row],[Часы ФАКТ]]),0) -> 172340 | K17: 172340 | L17: =IF(Таблица1[[#This Row],[Форма контрактации]]="ГПХ", Таблица1[[#This Row],[Итого со страховыми]]-Таблица1[[#This Row],[Заложено в ФП]], Таблица1[[#This Row],[Итого без овертаймов]]-Таблица1[[#This Row],[Заложено в ФП]]) -> 0 | M17: =IF(Таблица1[[#This Row],[Форма контрактации]]="ГПХ", Таблица1[[#This Row],[Итого без овертаймов]]*7.6%, "0") -> 0 | N17: =ROUND(Таблица1[[#This Row],[Итого без овертаймов]]+Таблица1[[#This Row],[Страховые взносы 7,8%]],0) -> 172340 | O17: 45748 | P17: 45778 | Q17: оплачено 13.05.2025
A18: 45748 | B18: Захаров Юрий | C18: СМЗ | D18: 0 | E18: Senior разработчик БД | F18: 0.3 | G18: =ROUND(Таблица1[[#This Row],[Загрузка респлан]]*VLOOKUP(Таблица1[[#This Row],[Месяц выполнения работ]],технический!$A$1:$B$25,2,FALSE),0) -> 53 | H18: 52 | I18: 2127.66 | J18: =ROUND(I18*IF(Таблица1[[#This Row],[Часы ФАКТ]]="",Таблица1[[#This Row],[Часы ПЛАН]],Таблица1[[#This Row],[Часы ФАКТ]]),0) -> 110638 | K18: 110638 | L18: =IF(Таблица1[[#This Row],[Форма контрактации]]="ГПХ", Таблица1[[#This Row],[Итого со страховыми]]-Таблица1[[#This Row],[Заложено в ФП]], Таблица1[[#This Row],[Итого без овертаймов]]-Таблица1[[#This Row],[Заложено в ФП]]) -> 0 | M18: =IF(Таблица1[[#This Row],[Форма контрактации]]="ГПХ", Таблица1[[#This Row],[Итого без овертаймов]]*7.6%, "0") -> 0 | N18: =ROUND(Таблица1[[#This Row],[Итого без овертаймов]]+Таблица1[[#This Row],[Страховые взносы 7,8%]],0) -> 110638 | O18: 45778 | P18: 45809 | Q18: оплачено 10.06.2025
A19: 45778 | B19: Захаров Юрий | C19: СМЗ | D19: 0 | E19: Senior разработчик БД | F19: 0.38 | G19: =ROUND(Таблица1[[#This Row],[Загрузка респлан]]*VLOOKUP(Таблица1[[#This Row],[Месяц выполнения работ]],технический!$A$1:$B$25,2,FALSE),0) -> 55 | H19: 54 | I19: 2127.66 | J19: =ROUND(I19*IF(Таблица1[[#This Row],[Часы ФАКТ]]="",Таблица1[[#This Row],[Часы ПЛАН]],Таблица1[[#This Row],[Часы ФАКТ]]),0) -> 114894 | K19: 114894 | L19: =IF(Таблица1[[#This Row],[Форма контрактации]]="ГПХ", Таблица1[[#This Row],[Итого со страховыми]]-Таблица1[[#This Row],[Заложено в ФП]], Таблица1[[#This Row],[Итого без овертаймов]]-Таблица1[[#This Row],[Заложено в ФП]]) -> 0 | M19: =IF(Таблица1[[#This Row],[Форма контрактации]]="ГПХ", Таблица1[[#This Row],[Итого без овертаймов]]*7.6%, "0") -> 0 | N19: =ROUND(Таблица1[[#This Row],[Итого без овертаймов]]+Таблица1[[#This Row],[Страховые взносы 7,8%]],0) -> 114894 | O19: 45778 | P19: 45809 | Q19: оплачено 10.06.2025
A20: 45809 | B20: Захаров Юрий | C20: СМЗ | D20: 0 | E20: Senior разработчик БД | F20: 0.41 | G20: =ROUND(Таблица1[[#This Row],[Загрузка респлан]]*VLOOKUP(Таблица1[[#This Row],[Месяц выполнения работ]],технический!$A$1:$B$25,2,FALSE),0) -> 62 | H20: 62 | I20: 2127.66 | J20: =ROUND(I20*IF(Таблица1[[#This Row],[Часы ФАКТ]]="",Таблица1[[#This Row],[Часы ПЛАН]],Таблица1[[#This Row],[Часы ФАКТ]]),0) -> 131915 | K20: 131915 | L20: =IF(Таблица1[[#This Row],[Форма контрактации]]="ГПХ", Таблица1[[#This Row],[Итого со страховыми]]-Таблица1[[#This Row],[Заложено в ФП]], Таблица1[[#This Row],[Итого без овертаймов]]-Таблица1[[#This Row],[Заложено в ФП]]) -> 0 | M20: =IF(Таблица1[[#This Row],[Форма контрактации]]="ГПХ", Таблица1[[#This Row],[Итого без овертаймов]]*7.6%, "0") -> 0 | N20: =ROUND(Таблица1[[#This Row],[Итого без овертаймов]]+Таблица1[[#This Row],[Страховые взносы 7,8%]],0) -> 131915 | O20: 45870 | P20: 45870 | Q20: оплачено 14.08.2025
A21: 45839 | B21: Захаров Юрий | C21: СМЗ | D21: 0 | E21: Senior разработчик БД | F21: 0.1 | G21: =ROUND(Таблица1[[#This Row],[Загрузка респлан]]*VLOOKUP(Таблица1[[#This Row],[Месяц выполнения работ]],технический!$A$1:$B$25,2,FALSE),0) -> 18 | H21: 18 | I21: 2127.66 | J21: =ROUND(I21*IF(Таблица1[[#This Row],[Часы ФАКТ]]="",Таблица1[[#This Row],[Часы ПЛАН]],Таблица1[[#This Row],[Часы ФАКТ]]),0) -> 38298 | K21: 38298 | L21: =IF(Таблица1[[#This Row],[Форма контрактации]]="ГПХ", Таблица1[[#This Row],[Итого со страховыми]]-Таблица1[[#This Row],[Заложено в ФП]], Таблица1[[#This Row],[Итого без овертаймов]]-Таблица1[[#This Row],[Заложено в ФП]]) -> 0 | M21: =IF(Таблица1[[#This Row],[Форма контрактации]]="ГПХ", Таблица1[[#This Row],[Итого без овертаймов]]*7.6%, "0") -> 0 | N21: =ROUND(Таблица1[[#This Row],[Итого без овертаймов]]+Таблица1[[#This Row],[Страховые взносы 7,8%]],0) -> 38298 | O21: 45870 | P21: 45870 | Q21: оплачено 14.08.2025
A22: 45870 | B22: Захаров Юрий | C22: СМЗ | D22: 0 | E22: Senior разработчик БД | F22: 0.08 | G22: =ROUND(Таблица1[[#This Row],[Загрузка респлан]]*VLOOKUP(Таблица1[[#This Row],[Месяц выполнения работ]],технический!$A$1:$B$25,2,FALSE),0) -> 13 | H22: 14 | I22: 2127.66 | J22: =ROUND(I22*IF(Таблица1[[#This Row],[Часы ФАКТ]]="",Таблица1[[#This Row],[Часы ПЛАН]],Таблица1[[#This Row],[Часы ФАКТ]]),0) -> 29787 | K22: 29787 | L22: =IF(Таблица1[[#This Row],[Форма контрактации]]="ГПХ", Таблица1[[#This Row],[Итого со страховыми]]-Таблица1[[#This Row],[Заложено в ФП]], Таблица1[[#This Row],[Итого без овертаймов]]-Таблица1[[#This Row],[Заложено в ФП]]) -> 0 | M22: =IF(Таблица1[[#This Row],[Форма контрактации]]="ГПХ", Таблица1[[#This Row],[Итого без овертаймов]]*7.6%, "0") -> 0 | N22: =ROUND(Таблица1[[#This Row],[Итого без овертаймов]]+Таблица1[[#This Row],[Страховые взносы 7,8%]],0) -> 29787 | O22: 45901 | P22: 45901 | Q22: оплачено 18.09.2025
A23: 45901 | B23: Захаров Юрий | C23: СМЗ | D23: 0 | E23: Senior разработчик БД | F23: 0.07 | G23: =ROUND(Таблица1[[#This Row],[Загрузка респлан]]*VLOOKUP(Таблица1[[#This Row],[Месяц выполнения работ]],технический!$A$1:$B$25,2,FALSE),0) -> 12 | H23: 12 | I23: 2127.66 | J23: =ROUND(I23*IF(Таблица1[[#This Row],[Часы ФАКТ]]="",Таблица1[[#This Row],[Часы ПЛАН]],Таблица1[[#This Row],[Часы ФАКТ]]),0) -> 25532 | K23: 25532 | L23: =IF(Таблица1[[#This Row],[Форма контрактации]]="ГПХ", Таблица1[[#This Row],[Итого со страховыми]]-Таблица1[[#This Row],[Заложено в ФП]], Таблица1[[#This Row],[Итого без овертаймов]]-Таблица1[[#This Row],[Заложено в ФП]]) -> 0 | M23: =IF(Таблица1[[#This Row],[Форма контрактации]]="ГПХ", Таблица1[[#This Row],[Итого без овертаймов]]*7.6%, "0") -> 0 | N23: =ROUND(Таблица1[[#This Row],[Итого без овертаймов]]+Таблица1[[#This Row],[Страховые взносы 7,8%]],0) -> 25532 | O23: 45931 | P23: 45931 | Q23: оплачено 23.10.2025
A24: 45931 | B24: Захаров Юрий | C24: СМЗ | D24: 0 | E24: Senior разработчик БД | F24: 0.27 | G24: =ROUND(Таблица1[[#This Row],[Загрузка респлан]]*VLOOKUP(Таблица1[[#This Row],[Месяц выполнения работ]],технический!$A$1:$B$25,2,FALSE),0) -> 50 | H24: 49 | I24: 2127.66 | J24: =ROUND(I24*IF(Таблица1[[#This Row],[Часы ФАКТ]]="",Таблица1[[#This Row],[Часы ПЛАН]],Таблица1[[#This Row],[Часы ФАКТ]]),0) -> 104255 | L24: =IF(Таблица1[[#This Row],[Форма контрактации]]="ГПХ", Таблица1[[#This Row],[Итого со страховыми]]-Таблица1[[#This Row],[Заложено в ФП]], Таблица1[[#This Row],[Итого без овертаймов]]-Таблица1[[#This Row],[Заложено в ФП]]) -> 104255 | M24: =IF(Таблица1[[#This Row],[Форма контрактации]]="ГПХ", Таблица1[[#This Row],[Итого без овертаймов]]*7.6%, "0") -> 0 | N24: =ROUND(Таблица1[[#This Row],[Итого без овертаймов]]+Таблица1[[#This Row],[Страховые взносы 7,8%]],0) -> 104255 | O24: 45962 | P24: 45962 | Q24: оплачено 20.11.2025
A25: 45962 | B25: Захаров Юрий | C25: СМЗ | D25: 0 | E25: Senior разработчик БД | F25: 0.31 | G25: =ROUND(Таблица1[[#This Row],[Загрузка респлан]]*VLOOKUP(Таблица1[[#This Row],[Месяц выполнения работ]],технический!$A$1:$B$25,2,FALSE),0) -> 47 | H25: 47 | I25: 2127.66 | J25: =ROUND(I25*IF(Таблица1[[#This Row],[Часы ФАКТ]]="",Таблица1[[#This Row],[Часы ПЛАН]],Таблица1[[#This Row],[Часы ФАКТ]]),0) -> 100000 | K25: 104255 | L25: =IF(Таблица1[[#This Row],[Форма контрактации]]="ГПХ", Таблица1[[#This Row],[Итого со страховыми]]-Таблица1[[#This Row],[Заложено в ФП]], Таблица1[[#This Row],[Итого без овертаймов]]-Таблица1[[#This Row],[Заложено в ФП]]) -> -4255 | M25: =IF(Таблица1[[#This Row],[Форма контрактации]]="ГПХ", Таблица1[[#This Row],[Итого без овертаймов]]*7.6%, "0") -> 0 | N25: =ROUND(Таблица1[[#This Row],[Итого без овертаймов]]+Таблица1[[#This Row],[Страховые взносы 7,8%]],0) -> 100000 | O25: 45992 | P25: 45992
A26: 45992 | B26: Захаров Юрий | C26: СМЗ | D26: 0 | E26: Senior разработчик БД | F26: 0.34 | G26: =ROUND(Таблица1[[#This Row],[Загрузка респлан]]*VLOOKUP(Таблица1[[#This Row],[Месяц выполнения работ]],технический!$A$1:$B$25,2,FALSE),0) -> 60 | H26: 71 | I26: 2127.66 | J26: =ROUND(I26*IF(Таблица1[[#This Row],[Часы ФАКТ]]="",Таблица1[[#This Row],[Часы ПЛАН]],Таблица1[[#This Row],[Часы ФАКТ]]),0) -> 151064 | K26: 253192 | L26: =IF(Таблица1[[#This Row],[Форма контрактации]]="ГПХ", Таблица1[[#This Row],[Итого со страховыми]]-Таблица1[[#This Row],[Заложено в ФП]], Таблица1[[#This Row],[Итого без овертаймов]]-Таблица1[[#This Row],[Заложено в ФП]]) -> -102128 | M26: =IF(Таблица1[[#This Row],[Форма контрактации]]="ГПХ", Таблица1[[#This Row],[Итого без овертаймов]]*7.6%, "0") -> 0 | N26: =ROUND(Таблица1[[#This Row],[Итого без овертаймов]]+Таблица1[[#This Row],[Страховые взносы 7,8%]],0) -> 151064 | O26: 46023 | P26: 46023
A27: 45809 | B27: Толстоусова Ольга | C27: ГПХ | D27: 0 | E27: Senior Аналитик | F27: 0.69 | G27: =ROUND(Таблица1[[#This Row],[Загрузка респлан]]*VLOOKUP(Таблица1[[#This Row],[Месяц выполнения работ]],технический!$A$1:$B$25,2,FALSE),0) -> 104 | H27: 104 | I27: 2710 | J27: =ROUND(I27*IF(Таблица1[[#This Row],[Часы ФАКТ]]="",Таблица1[[#This Row],[Часы ПЛАН]],Таблица1[[#This Row],[Часы ФАКТ]]),0) -> 281840 | K27: 0 | L27: =IF(Таблица1[[#This Row],[Форма контрактации]]="ГПХ", Таблица1[[#This Row],[Итого со страховыми]]-Таблица1[[#This Row],[Заложено в ФП]], Таблица1[[#This Row],[Итого без овертаймов]]-Таблица1[[#This Row],[Заложено в ФП]]) -> 303260 | M27: =IF(Таблица1[[#This Row],[Форма контрактации]]="ГПХ", Таблица1[[#This Row],[Итого без овертаймов]]*7.6%, "0") -> 21419.84 | N27: =ROUND(Таблица1[[#This Row],[Итого без овертаймов]]+Таблица1[[#This Row],[Страховые взносы 7,8%]],0) -> 303260 | O27: 45870 | P27: 45870 | Q27: оплачено 14.08.2025
A28: 45839 | B28: Толстоусова Ольга | C28: ГПХ | D28: 0 | E28: Senior Аналитик | F28: 0.3 | G28: =ROUND(Таблица1[[#This Row],[Загрузка респлан]]*VLOOKUP(Таблица1[[#This Row],[Месяц выполнения работ]],технический!$A$1:$B$25,2,FALSE),0) -> 55 | H28: 56 | I28: 2710 | J28: =ROUND(I28*IF(Таблица1[[#This Row],[Часы ФАКТ]]="",Таблица1[[#This Row],[Часы ПЛАН]],Таблица1[[#This Row],[Часы ФАКТ]]),0) -> 151760 | K28: 0 | L28: =IF(Таблица1[[#This Row],[Форма контрактации]]="ГПХ", Таблица1[[#This Row],[Итого со страховыми]]-Таблица1[[#This Row],[Заложено в ФП]], Таблица1[[#This Row],[Итого без овертаймов]]-Таблица1[[#This Row],[Заложено в ФП]]) -> 163294 | M28: =IF(Таблица1[[#This Row],[Форма контрактации]]="ГПХ", Таблица1[[#This Row],[Итого без овертаймов]]*7.6%, "0") -> 11533.76 | N28: =ROUND(Таблица1[[#This Row],[Итого без овертаймов]]+Таблица1[[#This Row],[Страховые взносы 7,8%]],0) -> 163294 | O28: 45870 | P28: 45870 | Q28: оплачено 14.08.2025
A29: 45870 | B29: Толстоусова Ольга | C29: ГПХ | D29: 0 | E29: Senior Аналитик | F29: 0.34 | G29: =ROUND(Таблица1[[#This Row],[Загрузка респлан]]*VLOOKUP(Таблица1[[#This Row],[Месяц выполнения работ]],технический!$A$1:$B$25,2,FALSE),0) -> 57 | H29: 57 | I29: 2710 | J29: =ROUND(I29*IF(Таблица1[[#This Row],[Часы ФАКТ]]="",Таблица1[[#This Row],[Часы ПЛАН]],Таблица1[[#This Row],[Часы ФАКТ]]),0) -> 154470 | K29: 466554 | L29: =IF(Таблица1[[#This Row],[Форма контрактации]]="ГПХ", Таблица1[[#This Row],[Итого со страховыми]]-Таблица1[[#This Row],[Заложено в ФП]], Таблица1[[#This Row],[Итого без овертаймов]]-Таблица1[[#This Row],[Заложено в ФП]]) -> -300344 | M29: =IF(Таблица1[[#This Row],[Форма контрактации]]="ГПХ", Таблица1[[#This Row],[Итого без овертаймов]]*7.6%, "0") -> 11739.72 | N29: =ROUND(Таблица1[[#This Row],[Итого без овертаймов]]+Таблица1[[#This Row],[Страховые взносы 7,8%]],0) -> 166210 | O29: 45901 | P29: 45901 | Q29: оплачено 30.09.2025
A30: 45901 | B30: Толстоусова Ольга | C30: ГПХ | D30: 0 | E30: Senior Аналитик | F30: 0.71 | G30: =ROUND(Таблица1[[#This Row],[Загрузка респлан]]*VLOOKUP(Таблица1[[#This Row],[Месяц выполнения работ]],технический!$A$1:$B$25,2,FALSE),0) -> 125 | H30: 125 | I30: 2710 | J30: =ROUND(I30*IF(Таблица1[[#This Row],[Часы ФАКТ]]="",Таблица1[[#This Row],[Часы ПЛАН]],Таблица1[[#This Row],[Часы ФАКТ]]),0) -> 338750 | K30: 166210 | L30: =IF(Таблица1[[#This Row],[Форма контрактации]]="ГПХ", Таблица1[[#This Row],[Итого со страховыми]]-Таблица1[[#This Row],[Заложено в ФП]], Таблица1[[#This Row],[Итого без овертаймов]]-Таблица1[[#This Row],[Заложено в ФП]]) -> 198285 | M30: =IF(Таблица1[[#This Row],[Форма контрактации]]="ГПХ", Таблица1[[#This Row],[Итого без овертаймов]]*7.6%, "0") -> 25745 | N30: =ROUND(Таблица1[[#This Row],[Итого без овертаймов]]+Таблица1[[#This Row],[Страховые взносы 7,8%]],0) -> 364495 | O30: 45931 | P30: 45931 | Q30: оплачено 09.10.2025
A31: 45931 | B31: Толстоусова Ольга | C31: ГПХ | D31: 0 | E31: Senior Аналитик | F31: 0 | G31: =ROUND(Таблица1[[#This Row],[Загрузка респлан]]*VLOOKUP(Таблица1[[#This Row],[Месяц выполнения работ]],технический!$A$1:$B$25,2,FALSE),0) -> 0 | H31: 0 | I31: 2710 | J31: =ROUND(I31*IF(Таблица1[[#This Row],[Часы ФАКТ]]="",Таблица1[[#This Row],[Часы ПЛАН]],Таблица1[[#This Row],[Часы ФАКТ]]),0) -> 0 | K31: 364495 | L31: =IF(Таблица1[[#This Row],[Форма контрактации]]="ГПХ", Таблица1[[#This Row],[Итого со страховыми]]-Таблица1[[#This Row],[Заложено в ФП]], Таблица1[[#This Row],[Итого без овертаймов]]-Таблица1[[#This Row],[Заложено в ФП]]) -> -364495 | M31: =IF(Таблица1[[#This Row],[Форма контрактации]]="ГПХ", Таблица1[[#This Row],[Итого без овертаймов]]*7.6%, "0") -> 0 | N31: =ROUND(Таблица1[[#This Row],[Итого без овертаймов]]+Таблица1[[#This Row],[Страховые взносы 7,8%]],0) -> 0 | Q31: договор подряда закончен
A32: 45778 | B32: Карпов Алексей | C32: СМЗ | D32: 0 | E32: Senior Архитектор решений | F32: 0.17 | G32: =ROUND(Таблица1[[#This Row],[Загрузка респлан]]*VLOOKUP(Таблица1[[#This Row],[Месяц выполнения работ]],технический!$A$1:$B$25,2,FALSE),0) -> 24 | H32: 24 | I32: 3600 | J32: =ROUND(I32*IF(Таблица1[[#This Row],[Часы ФАКТ]]="",Таблица1[[#This Row],[Часы ПЛАН]],Таблица1[[#This Row],[Часы ФАКТ]]),0) -> 86400 | K32: 0 | L32: =IF(Таблица1[[#This Row],[Форма контрактации]]="ГПХ", Таблица1[[#This Row],[Итого со страховыми]]-Таблица1[[#This Row],[Заложено в ФП]], Таблица1[[#This Row],[Итого без овертаймов]]-Таблица1[[#This Row],[Заложено в ФП]]) -> 86400 | M32: =IF(Таблица1[[#This Row],[Форма контрактации]]="ГПХ", Таблица1[[#This Row],[Итого без овертаймов]]*7.6%, "0") -> 0 | N32: =ROUND(Таблица1[[#This Row],[Итого без овертаймов]]+Таблица1[[#This Row],[Страховые взносы 7,8%]],0) -> 86400 | O32: 45839 | P32: 45870 | Q32: оплачено 12.08.2025
A33: 45809 | B33: Карпов Алексей | C33: СМЗ | D33: 0 | E33: Senior Архитектор решений | F33: 0.56 | G33: =ROUND(Таблица1[[#This Row],[Загрузка респлан]]*VLOOKUP(Таблица1[[#This Row],[Месяц выполнения работ]],технический!$A$1:$B$25,2,FALSE),0) -> 85 | H33: 84 | I33: 3600 | J33: =ROUND(I33*IF(Таблица1[[#This Row],[Часы ФАКТ]]="",Таблица1[[#This Row],[Часы ПЛАН]],Таблица1[[#This Row],[Часы ФАКТ]]),0) -> 302400 | K33: 0 | L33: =IF(Таблица1[[#This Row],[Форма контрактации]]="ГПХ", Таблица1[[#This Row],[Итого со страховыми]]-Таблица1[[#This Row],[Заложено в ФП]], Таблица1[[#This Row],[Итого без овертаймов]]-Таблица1[[#This Row],[Заложено в ФП]]) -> 302400 | M33: =IF(Таблица1[[#This Row],[Форма контрактации]]="ГПХ", Таблица1[[#This Row],[Итого без овертаймов]]*7.6%, "0") -> 0 | N33: =ROUND(Таблица1[[#This Row],[Итого без овертаймов]]+Таблица1[[#This Row],[Страховые взносы 7,8%]],0) -> 302400 | O33: 45839 | P33: 45870 | Q33: оплачено 12.08.2025
A34: 45870 | B34: Карпов Алексей | C34: СМЗ | D34: 0 | E34: Senior Архитектор решений | F34: 0.5 | G34: =ROUND(Таблица1[[#This Row],[Загрузка респлан]]*VLOOKUP(Таблица1[[#This Row],[Месяц выполнения работ]],технический!$A$1:$B$25,2,FALSE),0) -> 84 | H34: 84 | I34: 3600 | J34: =ROUND(I34*IF(Таблица1[[#This Row],[Часы ФАКТ]]="",Таблица1[[#This Row],[Часы ПЛАН]],Таблица1[[#This Row],[Часы ФАКТ]]),0) -> 302400 | K34: 388800 | L34: =IF(Таблица1[[#This Row],[Форма контрактации]]="ГПХ", Таблица1[[#This Row],[Итого со страховыми]]-Таблица1[[#This Row],[Заложено в ФП]], Таблица1[[#This Row],[Итого без овертаймов]]-Таблица1[[#This Row],[Заложено в ФП]]) -> -86400 | M34: =IF(Таблица1[[#This Row],[Форма контрактации]]="ГПХ", Таблица1[[#This Row],[Итого без овертаймов]]*7.6%, "0") -> 0 | N34: =ROUND(Таблица1[[#This Row],[Итого без овертаймов]]+Таблица1[[#This Row],[Страховые взносы 7,8%]],0) -> 302400 | O34: 45931 | P34: 45931 | Q34: оплачено 28.10.2025
A35: 45931 | B35: Карпов Алексей | C35: СМЗ | D35: 0 | E35: Senior Архитектор решений | F35: 0 | G35: =ROUND(Таблица1[[#This Row],[Загрузка респлан]]*VLOOKUP(Таблица1[[#This Row],[Месяц выполнения работ]],технический!$A$1:$B$25,2,FALSE),0) -> 0 | H35: 0 | I35: 3600 | J35: =ROUND(I35*IF(Таблица1[[#This Row],[Часы ФАКТ]]="",Таблица1[[#This Row],[Часы ПЛАН]],Таблица1[[#This Row],[Часы ФАКТ]]),0) -> 0 | K35: 302400 | L35: =IF(Таблица1[[#This Row],[Форма контрактации]]="ГПХ", Таблица1[[#This Row],[Итого со страховыми]]-Таблица1[[#This Row],[Заложено в ФП]], Таблица1[[#This Row],[Итого без овертаймов]]-Таблица1[[#This Row],[Заложено в ФП]]) -> -302400 | M35: =IF(Таблица1[[#This Row],[Форма контрактации]]="ГПХ", Таблица1[[#This Row],[Итого без овертаймов]]*7.6%, "0") -> 0 | N35: =ROUND(Таблица1[[#This Row],[Итого без овертаймов]]+Таблица1[[#This Row],[Страховые взносы 7,8%]],0) -> 0
A36: 45778 | B36: Черепанов Валерий | C36: СМЗ | D36: 0 | E36: Senior C++ | F36: 0.28 | G36: =ROUND(Таблица1[[#This Row],[Загрузка респлан]]*VLOOKUP(Таблица1[[#This Row],[Месяц выполнения работ]],технический!$A$1:$B$25,2,FALSE),0) -> 40 | H36: 40 | I36: 3130 | J36: =ROUND(I36*IF(Таблица1[[#This Row],[Часы ФАКТ]]="",Таблица1[[#This Row],[Часы ПЛАН]],Таблица1[[#This Row],[Часы ФАКТ]]),0) -> 125200 | K36: 0 | L36: =IF(Таблица1[[#This Row],[Форма контрактации]]="ГПХ", Таблица1[[#This Row],[Итого со страховыми]]-Таблица1[[#This Row],[Заложено в ФП]], Таблица1[[#This Row],[Итого без овертаймов]]-Таблица1[[#This Row],[Заложено в ФП]]) -> 125200 | M36: =IF(Таблица1[[#This Row],[Форма контрактации]]="ГПХ", Таблица1[[#This Row],[Итого без овертаймов]]*7.6%, "0") -> 0 | N36: =ROUND(Таблица1[[#This Row],[Итого без овертаймов]]+Таблица1[[#This Row],[Страховые взносы 7,8%]],0) -> 125200 | O36: 45839 | P36: 45839 | Q36: оплачено 31.07.2025
A37: 45809 | B37: Черепанов Валерий | C37: СМЗ | D37: 0 | E37: Senior C++ | F37: 0.85 | G37: =ROUND(Таблица1[[#This Row],[Загрузка респлан]]*VLOOKUP(Таблица1[[#This Row],[Месяц выполнения работ]],технический!$A$1:$B$25,2,FALSE),0) -> 128 | H37: 128 | I37: 3130 | J37: =ROUND(I37*IF(Таблица1[[#This Row],[Часы ФАКТ]]="",Таблица1[[#This Row],[Часы ПЛАН]],Таблица1[[#This Row],[Часы ФАКТ]]),0) -> 400640 | K37: 0 | L37: =IF(Таблица1[[#This Row],[Форма контрактации]]="ГПХ", Таблица1[[#This Row],[Итого со страховыми]]-Таблица1[[#This Row],[Заложено в ФП]], Таблица1[[#This Row],[Итого без овертаймов]]-Таблица1[[#This Row],[Заложено в ФП]]) -> 400640 | M37: =IF(Таблица1[[#This Row],[Форма контрактации]]="ГПХ", Таблица1[[#This Row],[Итого без овертаймов]]*7.6%, "0") -> 0 | N37: =ROUND(Таблица1[[#This Row],[Итого без овертаймов]]+Таблица1[[#This Row],[Страховые взносы 7,8%]],0) -> 400640 | O37: 45839 | P37: 45839 | Q37: оплачено 31.07.2025
A38: 45839 | B38: Черепанов Валерий | C38: СМЗ | D38: 0 | E38: Senior C++ | F38: 0 | G38: =ROUND(Таблица1[[#This Row],[Загрузка респлан]]*VLOOKUP(Таблица1[[#This Row],[Месяц выполнения работ]],технический!$A$1:$B$25,2,FALSE),0) -> 0 | J38: =ROUND(I38*IF(Таблица1[[#This Row],[Часы ФАКТ]]="",Таблица1[[#This Row],[Часы ПЛАН]],Таблица1[[#This Row],[Часы ФАКТ]]),0) -> 0 | K38: 525840 | L38: =IF(Таблица1[[#This Row],[Форма контрактации]]="ГПХ", Таблица1[[#This Row],[Итого со страховыми]]-Таблица1[[#This Row],[Заложено в ФП]], Таблица1[[#This Row],[Итого без овертаймов]]-Таблица1[[#This Row],[Заложено в ФП]]) -> -525840 | M38: =IF(Таблица1[[#This Row],[Форма контрактации]]="ГПХ", Таблица1[[#This Row],[Итого без овертаймов]]*7.6%, "0") -> 0 | N38: =ROUND(Таблица1[[#This Row],[Итого без овертаймов]]+Таблица1[[#This Row],[Страховые взносы 7,8%]],0) -> 0
A39: 45809 | B39: Сазонов Павел | C39: ИП | D39: 0 | E39: Senior DevOps | F39: 0.34 | G39: =ROUND(Таблица1[[#This Row],[Загрузка респлан]]*VLOOKUP(Таблица1[[#This Row],[Месяц выполнения работ]],технический!$A$1:$B$25,2,FALSE),0) -> 51 | H39: 52 | I39: 2500 | J39: =ROUND(I39*IF(Таблица1[[#This Row],[Часы ФАКТ]]="",Таблица1[[#This Row],[Часы ПЛАН]],Таблица1[[#This Row],[Часы ФАКТ]]),0) -> 130000 | K39: 0 | L39: =IF(Таблица1[[#This Row],[Форма контрактации]]="ГПХ", Таблица1[[#This Row],[Итого со страховыми]]-Таблица1[[#This Row],[Заложено в ФП]], Таблица1[[#This Row],[Итого без овертаймов]]-Таблица1[[#This Row],[Заложено в ФП]]) -> 130000 | M39: =IF(Таблица1[[#This Row],[Форма контрактации]]="ГПХ", Таблица1[[#This Row],[Итого без овертаймов]]*7.6%, "0") -> 0 | N39: =ROUND(Таблица1[[#This Row],[Итого без овертаймов]]+Таблица1[[#This Row],[Страховые взносы 7,8%]],0) -> 130000 | O39: 45839 | P39: 45870 | Q39: оплачено 14.08.2025
A40: 45870 | B40: Сазонов Павел | C40: ИП | D40: 0 | E40: Senior DevOps | F40: 0 | G40: =ROUND(Таблица1[[#This Row],[Загрузка респлан]]*VLOOKUP(Таблица1[[#This Row],[Месяц выполнения работ]],технический!$A$1:$B$25,2,FALSE),0) -> 0 | H40: 0 | I40: 2500 | J40: =ROUND(I40*IF(Таблица1[[#This Row],[Часы ФАКТ]]="",Таблица1[[#This Row],[Часы ПЛАН]],Таблица1[[#This Row],[Часы ФАКТ]]),0) -> 0 | K40: 130000 | L40: =IF(Таблица1[[#This Row],[Форма контрактации]]="ГПХ", Таблица1[[#This Row],[Итого со страховыми]]-Таблица1[[#This Row],[Заложено в ФП]], Таблица1[[#This Row],[Итого без овертаймов]]-Таблица1[[#This Row],[Заложено в ФП]]) -> -130000 | M40: =IF(Таблица1[[#This Row],[Форма контрактации]]="ГПХ", Таблица1[[#This Row],[Итого без овертаймов]]*7.6%, "0") -> 0 | N40: =ROUND(Таблица1[[#This Row],[Итого без овертаймов]]+Таблица1[[#This Row],[Страховые взносы 7,8%]],0) -> 0
A41: Итог | F41: =SUBTOTAL(109,Таблица1[Загрузка респлан]) -> 8.45 | G41: =SUBTOTAL(109,Таблица1[Часы ПЛАН]) -> 1355 | H41: =SUBTOTAL(109,Таблица1[Часы ФАКТ]) -> 1364.33 | J41: =SUBTOTAL(109,Таблица1[Итого без овертаймов]) -> 3572435 | K41: =SUBTOTAL(109,Таблица1[Заложено в ФП]) -> 3645002 | L41: =SUBTOTAL(109,Таблица1[Сумма изменений]) -> -2128 | M41: =SUBTOTAL(109,Таблица1[Страховые взносы 7,8%]) -> 70438.32 | N41: =SUBTOTAL(109,Таблица1[Итого со страховыми]) -> 3642874

Sheet расчеты_FIX
A13: Месяц выполнения работ | B13: Подрядчик | C13: Ставка НДС | D13: Итого за период без НДС | E13: Итого за период с НДС | F13: Заложено в ФП с НДС | G13: Сумма изменений с НДС | H13: Прогнозный месяц подписания Акта | I13: Прогнозный месяц выплат | J13: Комментарий
A14: 45992 | B14: ООО "Исходный код" | C14: 0.2 | D14: 37500000 | E14: =Таблица2[[#This Row],[Итого за период без НДС]]*(1+IF(ISNUMBER(Таблица2[[#This Row],[Ставка НДС]]),Таблица2[[#This Row],[Ставка НДС]],Таблица2[[#This Row],[Ставка НДС]]/100)) -> 45000000 | F14: 0 | G14: =Таблица2[[#This Row],[Итого за период с НДС]]-Таблица2[[#This Row],[Заложено в ФП с НДС]] -> 45000000 | H14: 45992 | I14: 45992
A15: 46143 | B15: МТИ | C15: 0.22 | D15: 8970462 | E15: =Таблица2[[#This Row],[Итого за период без НДС]]*(1+IF(ISNUMBER(Таблица2[[#This Row],[Ставка НДС]]),Таблица2[[#This Row],[Ставка НДС]],Таблица2[[#This Row],[Ставка НДС]]/100)) -> 10943964 | F15: 10943964 | G15: =Таблица2[[#This Row],[Итого за период с НДС]]-Таблица2[[#This Row],[Заложено в ФП с НДС]] -> 0 | H15: 46143 | I15: 46143
A16: Итог | D16: =SUBTOTAL(109,Таблица2[Итого за период без НДС]) -> 46470462 | E16: =SUBTOTAL(109,Таблица2[Итого за период с НДС]) -> 55943964 | F16: =SUBTOTAL(109,Таблица2[Заложено в ФП с НДС]) -> 10943964 | G16: =SUBTOTAL(109,Таблица2[Сумма изменений с НДС]) -> 45000000

Sheet Часы VS ФП
C1: Версия респлана
C2: Платформа Медиа 2527D v56
C3: Утвержденный бюджет | E3: Бюджет на согласовании | G3: Дельта
A4: ФИО подрядчика | B4: Форма контрактациии | C4: ФП (часы) | D4: ФП деньги (с НДС) | E4: ФП (часы) | F4: ФП деньги (с НДС) | G4: ФП (часы) | H4: ФП деньги (с НДС)
A5: {=_xlfn.UNIQUE(Таблица1[Специалист])} -> Захаров Юрий | B5: =IFERROR(_xlfn.XLOOKUP(A5,Таблица1[Специалист],Таблица1[Форма контрактации]),0) -> СМЗ | C5: 611.33 | D5: 1300703 | E5: =SUMIFS(Таблица1[Часы ПЛАН],Таблица1[Специалист],A5) -> 602 | F5: =SUMIFS(Таблица1[Итого со страховыми],Таблица1[Специалист],A5) -> 1298575 | G5: =E5-C5 -> -9.33 | H5: =F5-D5 -> -2128
A6: Толстоусова Ольга | B6: =IFERROR(_xlfn.XLOOKUP(A6,Таблица1[Специалист],Таблица1[Форма контрактации]),0) -> ГПХ | C6: 341 | D6: 997259 | E6: =SUMIFS(Таблица1[Часы ПЛАН],Таблица1[Специалист],A6) -> 341 | F6: =SUMIFS(Таблица1[Итого со страховыми],Таблица1[Специалист],A6) -> 997259 | G6: =E6-C6 -> 0 | H6: =F6-D6 -> 0
A7: Карпов Алексей | B7: =IFERROR(_xlfn.XLOOKUP(A7,Таблица1[Специалист],Таблица1[Форма контрактации]),0) -> СМЗ | C7: 193 | D7: 691200 | E7: 193 | F7: =SUMIFS(Таблица1[Итого со страховыми],Таблица1[Специалист],A7) -> 691200 | G7: =E7-C7 -> 0 | H7: =F7-D7 -> 0
A8: Черепанов Валерий | B8: =IFERROR(_xlfn.XLOOKUP(A8,Таблица1[Специалист],Таблица1[Форма контрактации]),0) -> СМЗ | C8: 168 | D8: 525840 | E8: =SUMIFS(Таблица1[Часы ПЛАН],Таблица1[Специалист],A8) -> 168 | F8: =SUMIFS(Таблица1[Итого со страховыми],Таблица1[Специалист],A8) -> 525840 | G8: =E8-C8 -> 0 | H8: =F8-D8 -> 0
A9: Сазонов Павел | B9: =IFERROR(_xlfn.XLOOKUP(A9,Таблица1[Специалист],Таблица1[Форма контрактации]),0) -> ИП | C9: 51 | D9: 130000 | E9: =SUMIFS(Таблица1[Часы ПЛАН],Таблица1[Специалист],A9) -> 51 | F9: =SUMIFS(Таблица1[Итого со страховыми],Таблица1[Специалист],A9) -> 130000 | G9: =E9-C9 -> 0 | H9: =F9-D9 -> 0
A10: Итог: | C10: =SUM(C5:C9) -> 1364.33 | D10: =SUM(D5:D9) -> 3645002 | E10: =SUM(E5:E9) -> 1355 | F10: =SUM(F5:F9) -> 3642874 | G10: =SUM(G5:G9) -> -9.33 | H10: =SUM(H5:H9) -> -2128

Sheet шаблон расчета проекта
A1: ФИО | B1: Форма контрактования | C1: Процент страховых взносов (для расчета) | D1: Ставка НДС | E1: Ставка net/без НДС | F1: 44927 | G1: 44958 | H1: 44986 | I1: 45017 | J1: 45047 | K1: 45078 | L1: 45108 | M1: 45139 | N1: 45170 | O1: 45200 | P1: 45231 | Q1: 45261 | R1: 45292 | S1: 45323 | T1: 45352 | U1: 45383 | V1: 45413 | W1: 45444 | X1: 45474 | Y1: 45505 | Z1: 45536 | AA1: 45566 | AB1: 45597 | AC1: 45627 | AD1: 45658 | AE1: 45689 | AF1: 45717 | AG1: 45748 | AH1: 45778 | AI1: 45809 | AJ1: 45839 | AK1: 45870 | AL1: 45901 | AM1: 45931 | AN1: 45962 | AO1: 45992 | AP1: 46023 | AQ1: 46054 | AR1: 46082 | AS1: 46113 | AT1: 46143 | AU1: 46174 | AV1: 46204 | AW1: 46235 | AX1: 46266 | AY1: 46296 | AZ1: 46327 | BA1: 46357 | BB1: 46388 | BC1: 46419 | BD1: 46447 | BE1: 46478 | BF1: 46508 | BG1: 46539 | BH1: 46569 | BI1: 46600 | BJ1: 46631 | BK1: 46661 | BL1: 46692 | BM1: 46722 | BN1: 46753 | BO1: 46784 | BP1: 46813 | BQ1: 46844 | BR1: 46874 | BS1: 46905 | BT1: 46935 | BU1: 46966 | BV1: 46997 | BW1: 47027 | BX1: 47058 | BY1: 47088 | BZ1: ИТОГО
A3: Ресурсы Time&Material:
A4: {=_xlfn.UNIQUE(Таблица1[Специалист])} -> Захаров Юрий | B4: =IF(ISERROR(SEARCH("ООО",IFERROR(_xlfn.XLOOKUP(A4,'расчеты_T&M'!B:B,'расчеты_T&M'!C:C),0))),IF(ISERROR(SEARCH("СМЗ",IFERROR(_xlfn.XLOOKUP(A4,'расчеты_T&M'!B:B,'расчеты_T&M'!C:C),0))),IF(ISERROR(SEARCH("ИП",IFERROR(_xlfn.XLOOKUP(A4,'расчеты_T&M'!B:B,'расчеты_T&M'!C:C),0))),IF(ISERROR(SEARCH("ГПХ",IFERROR(_xlfn.XLOOKUP(A4,'расчеты_T&M'!B:B,'расчеты_T&M'!C:C),0))),"","ГПХ"),"ИП"),"СМЗ"),"ЮЛ") -> СМЗ | C4: =IF(B4="ГПХ",7.8%,0%) -> 0 | D4: =IFERROR(_xlfn.XLOOKUP(A4,Таблица1[Специалист],Таблица1[Ставка НДС]),0) -> 0 | E4: =IFERROR(_xlfn.XLOOKUP(A4,Таблица1[Специалист],Таблица1[Ставка Gross])/(1+IFERROR(_xlfn.XLOOKUP(A4,Таблица1[Специалист],Таблица1[Ставка НДС]),0)),0) -> 2127.66 | F4: =SUMIFS(Таблица1[[Загрузка респлан]:[Загрузка респлан]],Таблица1[[Специалист]:[Специалист]],'шаблон расчета проекта'!$A4,Таблица1[[Месяц выполнения работ]:[Месяц выполнения работ]],'шаблон расчета проекта'!F$1) -> 0 | G4: =SUMIFS(Таблица1[[Загрузка респлан]:[Загрузка респлан]],Таблица1[[Специалист]:[Специалист]],'шаблон расчета проекта'!$A4,Таблица1[[Месяц выполнения работ]:[Месяц выполнения работ]],'шаблон расчета проекта'!G$1) -> 0 | H4: =SUMIFS(Таблица1[[Загрузка респлан]:[Загрузка респлан]],Таблица1[[Специалист]:[Специалист]],'шаблон расчета проекта'!$A4,Таблица1[[Месяц выполнения работ]:[Месяц выполнения работ]],'шаблон расчета проекта'!H$1) -> 0 | I4: =SUMIFS(Таблица1[[Загрузка респлан]:[Загрузка респлан]],Таблица1[[Специалист]:[Специалист]],'шаблон расчета проекта'!$A4,Таблица1[[Месяц выполнения работ]:[Месяц выполнения работ]],'шаблон расчета проекта'!I$1) -> 0 | J4: =SUMIFS(Таблица1[[Загрузка респлан]:[Загрузка респлан]],Таблица1[[Специалист]:[Специалист]],'шаблон расчета проекта'!$A4,Таблица1[[Месяц выполнения работ]:[Месяц выполнения работ]],'шаблон расчета проекта'!J$1) -> 0 | K4: =SUMIFS(Таблица1[[Загрузка респлан]:[Загрузка респлан]],Таблица1[[Специалист]:[Специалист]],'шаблон расчета проекта'!$A4,Таблица1[[Месяц выполнения работ]:[Месяц выполнения работ]],'шаблон расчета проекта'!K$1) -> 0 | L4: =SUMIFS(Таблица1[[Загрузка респлан]:[Загрузка респлан]],Таблица1[[Специалист]:[Специалист]],'шаблон расчета проекта'!$A4,Таблица1[[Месяц выполнения работ]:[Месяц выполнения работ]],'шаблон расчета проекта'!L$1) -> 0 | M4: =SUMIFS(Таблица1[[Загрузка респлан]:[Загрузка респлан]],Таблица1[[Специалист]:[Специалист]],'шаблон расчета проекта'!$A4,Таблица1[[Месяц выполнения работ]:[Месяц выполнения работ]],'шаблон расчета проекта'!M$1) -> 0 | ... BY4: =SUMIFS(Таблица1[[Загрузка респлан]:[Загрузка респлан]],Таблица1[[Специалист]:[Специалист]],'шаблон расчета проекта'!$A4,Таблица1[[Месяц выполнения работ]:[Месяц выполнения работ]],'шаблон расчета проекта'!BY$1) -> 0 | BZ4: =SUM(F4:BY4) -> 3.71 | CA4: check
A5: Толстоусова Ольга | B5: =IF(ISERROR(SEARCH("ООО",IFERROR(_xlfn.XLOOKUP(A5,'расчеты_T&M'!B:B,'расчеты_T&M'!C:C),0))),IF(ISERROR(SEARCH("СМЗ",IFERROR(_xlfn.XLOOKUP(A5,'расчеты_T&M'!B:B,'расчеты_T&M'!C:C),0))),IF(ISERROR(SEARCH("ИП",IFERROR(_xlfn.XLOOKUP(A5,'расчеты_T&M'!B:B,'расчеты_T&M'!C:C),0))),IF(ISERROR(SEARCH("ГПХ",IFERROR(_xlfn.XLOOKUP(A5,'расчеты_T&M'!B:B,'расчеты_T&M'!C:C),0))),"","ГПХ"),"ИП"),"СМЗ"),"ЮЛ") -> ГПХ | C5: =IF(B5="ГПХ",7.8%,0%) -> 0.078 | D5: =IFERROR(_xlfn.XLOOKUP(A5,Таблица1[Специалист],Таблица1[Ставка НДС]),0) -> 0 | E5: =IFERROR(_xlfn.XLOOKUP(A5,Таблица1[Специалист],Таблица1[Ставка Gross])/(1+IFERROR(_xlfn.XLOOKUP(A5,Таблица1[Специалист],Таблица1[Ставка НДС]),0)),0) -> 2710 | F5: =SUMIFS(Таблица1[[Загрузка респлан]:[Загрузка респлан]],Таблица1[[Специалист]:[Специалист]],'шаблон расчета проекта'!$A5,Таблица1[[Месяц выполнения работ]:[Месяц выполнения работ]],'шаблон расчета проекта'!F$1) -> 0 | G5: =SUMIFS(Таблица1[[Загрузка респлан]:[Загрузка респлан]],Таблица1[[Специалист]:[Специалист]],'шаблон расчета проекта'!$A5,Таблица1[[Месяц выполнения работ]:[Месяц выполнения работ]],'шаблон расчета проекта'!G$1) -> 0 | H5: =SUMIFS(Таблица1[[Загрузка респлан]:[Загрузка респлан]],Таблица1[[Специалист]:[Специалист]],'шаблон расчета проекта'!$A5,Таблица1[[Месяц выполнения работ]:[Месяц выполнения работ]],'шаблон расчета проекта'!H$1) -> 0 | I5: =SUMIFS(Таблица1[[Загрузка респлан]:[Загрузка респлан]],Таблица1[[Специалист]:[Специалист]],'шаблон расчета проекта'!$A5,Таблица1[[Месяц выполнения работ]:[Месяц выполнения работ]],'шаблон расчета проекта'!I$1) -> 0 | J5: =SUMIFS(Таблица1[[Загрузка респлан]:[Загрузка респлан]],Таблица1[[Специалист]:[Специалист]],'шаблон расчета проекта'!$A5,Таблица1[[Месяц выполнения работ]:[Месяц выполнения работ]],'шаблон расчета проекта'!J$1) -> 0 | K5: =SUMIFS(Таблица1[[Загрузка респлан]:[Загрузка респлан]],Таблица1[[Специалист]:[Специалист]],'шаблон расчета проекта'!$A5,Таблица1[[Месяц выполнения работ]:[Месяц выполнения работ]],'шаблон расчета проекта'!K$1) -> 0 | L5: =SUMIFS(Таблица1[[Загрузка респлан]:[Загрузка респлан]],Таблица1[[Специалист]:[Специалист]],'шаблон расчета проекта'!$A5,Таблица1[[Месяц выполнения работ]:[Месяц выполнения работ]],'шаблон расчета проекта'!L$1) -> 0 | M5: =SUMIFS(Таблица1[[Загрузка респлан]:[Загрузка респлан]],Таблица1[[Специалист]:[Специалист]],'шаблон расчета проекта'!$A5,Таблица1[[Месяц выполнения работ]:[Месяц выполнения работ]],'шаблон расчета проекта'!M$1) -> 0 | ... BY5: =SUMIFS(Таблица1[[Загрузка респлан]:[Загрузка респлан]],Таблица1[[Специалист]:[Специалист]],'шаблон расчета проекта'!$A5,Таблица1[[Месяц выполнения работ]:[Месяц выполнения работ]],'шаблон расчета проекта'!BY$1) -> 0 | BZ5: =SUM(F5:BY5) -> 2.04
A6: Карпов Алексей | B6: =IF(ISERROR(SEARCH("ООО",IFERROR(_xlfn.XLOOKUP(A6,'расчеты_T&M'!B:B,'расчеты_T&M'!C:C),0))),IF(ISERROR(SEARCH("СМЗ",IFERROR(_xlfn.XLOOKUP(A6,'расчеты_T&M'!B:B,'расчеты_T&M'!C:C),0))),IF(ISERROR(SEARCH("ИП",IFERROR(_xlfn.XLOOKUP(A6,'расчеты_T&M'!B:B,'расчеты_T&M'!C:C),0))),IF(ISERROR(SEARCH("ГПХ",IFERROR(_xlfn.XLOOKUP(A6,'расчеты_T&M'!B:B,'расчеты_T&M'!C:C),0))),"","ГПХ"),"ИП"),"СМЗ"),"ЮЛ") -> СМЗ | C6: =IF(B6="ГПХ",7.8%,0%) -> 0 | D6: =IFERROR(_xlfn.XLOOKUP(A6,Таблица1[Специалист],Таблица1[Ставка НДС]),0) -> 0 | E6: =IFERROR(_xlfn.XLOOKUP(A6,Таблица1[Специалист],Таблица1[Ставка Gross])/(1+IFERROR(_xlfn.XLOOKUP(A6,Таблица1[Специалист],Таблица1[Ставка НДС]),0)),0) -> 3600 | F6: =SUMIFS(Таблица1[[Загрузка респлан]:[Загрузка респлан]],Таблица1[[Специалист]:[Специалист]],'шаблон расчета проекта'!$A6,Таблица1[[Месяц выполнения работ]:[Месяц выполнения работ]],'шаблон расчета проекта'!F$1) -> 0 | G6: =SUMIFS(Таблица1[[Загрузка респлан]:[Загрузка респлан]],Таблица1[[Специалист]:[Специалист]],'шаблон расчета проекта'!$A6,Таблица1[[Месяц выполнения работ]:[Месяц выполнения работ]],'шаблон расчета проекта'!G$1) -> 0 | H6: =SUMIFS(Таблица1[[Загрузка респлан]:[Загрузка респлан]],Таблица1[[Специалист]:[Специалист]],'шаблон расчета проекта'!$A6,Таблица1[[Месяц выполнения работ]:[Месяц выполнения работ]],'шаблон расчета проекта'!H$1) -> 0 | I6: =SUMIFS(Таблица1[[Загрузка респлан]:[Загрузка респлан]],Таблица1[[Специалист]:[Специалист]],'шаблон расчета проекта'!$A6,Таблица1[[Месяц выполнения работ]:[Месяц выполнения работ]],'шаблон расчета проекта'!I$1) -> 0 | J6: =SUMIFS(Таблица1[[Загрузка респлан]:[Загрузка респлан]],Таблица1[[Специалист]:[Специалист]],'шаблон расчета проекта'!$A6,Таблица1[[Месяц выполнения работ]:[Месяц выполнения работ]],'шаблон расчета проекта'!J$1) -> 0 | K6: =SUMIFS(Таблица1[[Загрузка респлан]:[Загрузка респлан]],Таблица1[[Специалист]:[Специалист]],'шаблон расчета проекта'!$A6,Таблица1[[Месяц выполнения работ]:[Месяц выполнения работ]],'шаблон расчета проекта'!K$1) -> 0 | L6: =SUMIFS(Таблица1[[Загрузка респлан]:[Загрузка респлан]],Таблица1[[Специалист]:[Специалист]],'шаблон расчета проекта'!$A6,Таблица1[[Месяц выполнения работ]:[Месяц выполнения работ]],'шаблон расчета проекта'!L$1) -> 0 | M6: =SUMIFS(Таблица1[[Загрузка респлан]:[Загрузка респлан]],Таблица1[[Специалист]:[Специалист]],'шаблон расчета проекта'!$A6,Таблица1[[Месяц выполнения работ]:[Месяц выполнения работ]],'шаблон расчета проекта'!M$1) -> 0 | ... BY6: =SUMIFS(Таблица1[[Загрузка респлан]:[Загрузка респлан]],Таблица1[[Специалист]:[Специалист]],'шаблон расчета проекта'!$A6,Таблица1[[Месяц выполнения работ]:[Месяц выполнения работ]],'шаблон расчета проекта'!BY$1) -> 0 | BZ6: =SUM(F6:BY6) -> 1.23
A7: Черепанов Валерий | B7: =IF(ISERROR(SEARCH("ООО",IFERROR(_xlfn.XLOOKUP(A7,'расчеты_T&M'!B:B,'расчеты_T&M'!C:C),0))),IF(ISERROR(SEARCH("СМЗ",IFERROR(_xlfn.XLOOKUP(A7,'расчеты_T&M'!B:B,'расчеты_T&M'!C:C),0))),IF(ISERROR(SEARCH("ИП",IFERROR(_xlfn.XLOOKUP(A7,'расчеты_T&M'!B:B,'расчеты_T&M'!C:C),0))),IF(ISERROR(SEARCH("ГПХ",IFERROR(_xlfn.XLOOKUP(A7,'расчеты_T&M'!B:B,'расчеты_T&M'!C:C),0))),"","ГПХ"),"ИП"),"СМЗ"),"ЮЛ") -> СМЗ | C7: =IF(B7="ГПХ",7.8%,0%) -> 0 | D7: =IFERROR(_xlfn.XLOOKUP(A7,Таблица1[Специалист],Таблица1[Ставка НДС]),0) -> 0 | E7: =IFERROR(_xlfn.XLOOKUP(A7,Таблица1[Специалист],Таблица1[Ставка Gross])/(1+IFERROR(_xlfn.XLOOKUP(A7,Таблица1[Специалист],Таблица1[Ставка НДС]),0)),0) -> 3130 | F7: =SUMIFS(Таблица1[[Загрузка респлан]:[Загрузка респлан]],Таблица1[[Специалист]:[Специалист]],'шаблон расчета проекта'!$A7,Таблица1[[Месяц выполнения работ]:[Месяц выполнения работ]],'шаблон расчета проекта'!F$1) -> 0 | G7: =SUMIFS(Таблица1[[Загрузка респлан]:[Загрузка респлан]],Таблица1[[Специалист]:[Специалист]],'шаблон расчета проекта'!$A7,Таблица1[[Месяц выполнения работ]:[Месяц выполнения работ]],'шаблон расчета проекта'!G$1) -> 0 | H7: =SUMIFS(Таблица1[[Загрузка респлан]:[Загрузка респлан]],Таблица1[[Специалист]:[Специалист]],'шаблон расчета проекта'!$A7,Таблица1[[Месяц выполнения работ]:[Месяц выполнения работ]],'шаблон расчета проекта'!H$1) -> 0 | I7: =SUMIFS(Таблица1[[Загрузка респлан]:[Загрузка респлан]],Таблица1[[Специалист]:[Специалист]],'шаблон расчета проекта'!$A7,Таблица1[[Месяц выполнения работ]:[Месяц выполнения работ]],'шаблон расчета проекта'!I$1) -> 0 | J7: =SUMIFS(Таблица1[[Загрузка респлан]:[Загрузка респлан]],Таблица1[[Специалист]:[Специалист]],'шаблон расчета проекта'!$A7,Таблица1[[Месяц выполнения работ]:[Месяц выполнения работ]],'шаблон расчета проекта'!J$1) -> 0 | K7: =SUMIFS(Таблица1[[Загрузка респлан]:[Загрузка респлан]],Таблица1[[Специалист]:[Специалист]],'шаблон расчета проекта'!$A7,Таблица1[[Месяц выполнения работ]:[Месяц выполнения работ]],'шаблон расчета проекта'!K$1) -> 0 | L7: =SUMIFS(Таблица1[[Загрузка респлан]:[Загрузка респлан]],Таблица1[[Специалист]:[Специалист]],'шаблон расчета проекта'!$A7,Таблица1[[Месяц выполнения работ]:[Месяц выполнения работ]],'шаблон расчета проекта'!L$1) -> 0 | M7: =SUMIFS(Таблица1[[Загрузка респлан]:[Загрузка респлан]],Таблица1[[Специалист]:[Специалист]],'шаблон расчета проекта'!$A7,Таблица1[[Месяц выполнения работ]:[Месяц выполнения работ]],'шаблон расчета проекта'!M$1) -> 0 | ... BY7: =SUMIFS(Таблица1[[Загрузка респлан]:[Загрузка респлан]],Таблица1[[Специалист]:[Специалист]],'шаблон расчета проекта'!$A7,Таблица1[[Месяц выполнения работ]:[Месяц выполнения работ]],'шаблон расчета проекта'!BY$1) -> 0 | BZ7: =SUM(F7:BY7) -> 1.13
A8: Сазонов Павел | B8: =IF(ISERROR(SEARCH("ООО",IFERROR(_xlfn.XLOOKUP(A8,'расчеты_T&M'!B:B,'расчеты_T&M'!C:C),0))),IF(ISERROR(SEARCH("СМЗ",IFERROR(_xlfn.XLOOKUP(A8,'расчеты_T&M'!B:B,'расчеты_T&M'!C:C),0))),IF(ISERROR(SEARCH("ИП",IFERROR(_xlfn.XLOOKUP(A8,'расчеты_T&M'!B:B,'расчеты_T&M'!C:C),0))),IF(ISERROR(SEARCH("ГПХ",IFERROR(_xlfn.XLOOKUP(A8,'расчеты_T&M'!B:B,'расчеты_T&M'!C:C),0))),"","ГПХ"),"ИП"),"СМЗ"),"ЮЛ") -> ИП | C8: =IF(B8="ГПХ",7.8%,0%) -> 0 | D8: =IFERROR(_xlfn.XLOOKUP(A8,Таблица1[Специалист],Таблица1[Ставка НДС]),0) -> 0 | E8: =IFERROR(_xlfn.XLOOKUP(A8,Таблица1[Специалист],Таблица1[Ставка Gross])/(1+IFERROR(_xlfn.XLOOKUP(A8,Таблица1[Специалист],Таблица1[Ставка НДС]),0)),0) -> 2500 | F8: =SUMIFS(Таблица1[[Загрузка респлан]:[Загрузка респлан]],Таблица1[[Специалист]:[Специалист]],'шаблон расчета проекта'!$A8,Таблица1[[Месяц выполнения работ]:[Месяц выполнения работ]],'шаблон расчета проекта'!F$1) -> 0 | G8: =SUMIFS(Таблица1[[Загрузка респлан]:[Загрузка респлан]],Таблица1[[Специалист]:[Специалист]],'шаблон расчета проекта'!$A8,Таблица1[[Месяц выполнения работ]:[Месяц выполнения работ]],'шаблон расчета проекта'!G$1) -> 0 | H8: =SUMIFS(Таблица1[[Загрузка респлан]:[Загрузка респлан]],Таблица1[[Специалист]:[Специалист]],'шаблон расчета проекта'!$A8,Таблица1[[Месяц выполнения работ]:[Месяц выполнения работ]],'шаблон расчета проекта'!H$1) -> 0 | I8: =SUMIFS(Таблица1[[Загрузка респлан]:[Загрузка респлан]],Таблица1[[Специалист]:[Специалист]],'шаблон расчета проекта'!$A8,Таблица1[[Месяц выполнения работ]:[Месяц выполнения работ]],'шаблон расчета проекта'!I$1) -> 0 | J8: =SUMIFS(Таблица1[[Загрузка респлан]:[Загрузка респлан]],Таблица1[[Специалист]:[Специалист]],'шаблон расчета проекта'!$A8,Таблица1[[Месяц выполнения работ]:[Месяц выполнения работ]],'шаблон расчета проекта'!J$1) -> 0 | K8: =SUMIFS(Таблица1[[Загрузка респлан]:[Загрузка респлан]],Таблица1[[Специалист]:[Специалист]],'шаблон расчета проекта'!$A8,Таблица1[[Месяц выполнения работ]:[Месяц выполнения работ]],'шаблон расчета проекта'!K$1) -> 0 | L8: =SUMIFS(Таблица1[[Загрузка респлан]:[Загрузка респлан]],Таблица1[[Специалист]:[Специалист]],'шаблон расчета проекта'!$A8,Таблица1[[Месяц выполнения работ]:[Месяц выполнения работ]],'шаблон расчета проекта'!L$1) -> 0 | M8: =SUMIFS(Таблица1[[Загрузка респлан]:[Загрузка респлан]],Таблица1[[Специалист]:[Специалист]],'шаблон расчета проекта'!$A8,Таблица1[[Месяц выполнения работ]:[Месяц выполнения работ]],'шаблон расчета проекта'!M$1) -> 0 | ... BY8: =SUMIFS(Таблица1[[Загрузка респлан]:[Загрузка респлан]],Таблица1[[Специалист]:[Специалист]],'шаблон расчета проекта'!$A8,Таблица1[[Месяц выполнения работ]:[Месяц выполнения работ]],'шаблон расчета проекта'!BY$1) -> 0 | BZ8: =SUM(F8:BY8) -> 0.34
B9: =IF(ISERROR(SEARCH("ООО",IFERROR(_xlfn.XLOOKUP(A9,'расчеты_T&M'!B:B,'расчеты_T&M'!C:C),0))),IF(ISERROR(SEARCH("СМЗ",IFERROR(_xlfn.XLOOKUP(A9,'расчеты_T&M'!B:B,'расчеты_T&M'!C:C),0))),IF(ISERROR(SEARCH("ИП",IFERROR(_xlfn.XLOOKUP(A9,'расчеты_T&M'!B:B,'расчеты_T&M'!C:C),0))),IF(ISERROR(SEARCH("ГПХ",IFERROR(_xlfn.XLOOKUP(A9,'расчеты_T&M'!B:B,'расчеты_T&M'!C:C),0))),"","ГПХ"),"ИП"),"СМЗ"),"ЮЛ") | C9: =IF(B9="ГПХ",7.8%,0%) -> 0 | D9: =IFERROR(_xlfn.XLOOKUP(A9,Таблица1[Специалист],Таблица1[Ставка НДС]),0) -> 0 | E9: =IFERROR(_xlfn.XLOOKUP(A9,Таблица1[Специалист],Таблица1[Ставка Gross])/(1+IFERROR(_xlfn.XLOOKUP(A9,Таблица1[Специалист],Таблица1[Ставка НДС]),0)),0) -> 0 | F9: =SUMIFS(Таблица1[[Загрузка респлан]:[Загрузка респлан]],Таблица1[[Специалист]:[Специалист]],'шаблон расчета проекта'!$A9,Таблица1[[Месяц выполнения работ]:[Месяц выполнения работ]],'шаблон расчета проекта'!F$1) -> 0 | G9: =SUMIFS(Таблица1[[Загрузка респлан]:[Загрузка респлан]],Таблица1[[Специалист]:[Специалист]],'шаблон расчета проекта'!$A9,Таблица1[[Месяц выполнения работ]:[Месяц выполнения работ]],'шаблон расчета проекта'!G$1) -> 0 | H9: =SUMIFS(Таблица1[[Загрузка респлан]:[Загрузка респлан]],Таблица1[[Специалист]:[Специалист]],'шаблон расчета проекта'!$A9,Таблица1[[Месяц выполнения работ]:[Месяц выполнения работ]],'шаблон расчета проекта'!H$1) -> 0 | I9: =SUMIFS(Таблица1[[Загрузка респлан]:[Загрузка респлан]],Таблица1[[Специалист]:[Специалист]],'шаблон расчета проекта'!$A9,Таблица1[[Месяц выполнения работ]:[Месяц выполнения работ]],'шаблон расчета проекта'!I$1) -> 0 | J9: =SUMIFS(Таблица1[[Загрузка респлан]:[Загрузка респлан]],Таблица1[[Специалист]:[Специалист]],'шаблон расчета проекта'!$A9,Таблица1[[Месяц выполнения работ]:[Месяц выполнения работ]],'шаблон расчета проекта'!J$1) -> 0 | K9: =SUMIFS(Таблица1[[Загрузка респлан]:[Загрузка респлан]],Таблица1[[Специалист]:[Специалист]],'шаблон расчета проекта'!$A9,Таблица1[[Месяц выполнения работ]:[Месяц выполнения работ]],'шаблон расчета проекта'!K$1) -> 0 | L9: =SUMIFS(Таблица1[[Загрузка респлан]:[Загрузка респлан]],Таблица1[[Специалист]:[Специалист]],'шаблон расчета проекта'!$A9,Таблица1[[Месяц выполнения работ]:[Месяц выполнения работ]],'шаблон расчета проекта'!L$1) -> 0 | M9: =SUMIFS(Таблица1[[Загрузка респлан]:[Загрузка респлан]],Таблица1[[Специалист]:[Специалист]],'шаблон расчета проекта'!$A9,Таблица1[[Месяц выполнения работ]:[Месяц выполнения работ]],'шаблон расчета проекта'!M$1) -> 0 | ... BY9: =SUMIFS(Таблица1[[Загрузка респлан]:[Загрузка респлан]],Таблица1[[Специалист]:[Специалист]],'шаблон расчета проекта'!$A9,Таблица1[[Месяц выполнения работ]:[Месяц выполнения работ]],'шаблон расчета проекта'!BY$1) -> 0 | BZ9: =SUM(F9:BY9) -> 0
B10: =IF(ISERROR(SEARCH("ООО",IFERROR(_xlfn.XLOOKUP(A10,'расчеты_T&M'!B:B,'расчеты_T&M'!C:C),0))),IF(ISERROR(SEARCH("СМЗ",IFERROR(_xlfn.XLOOKUP(A10,'расчеты_T&M'!B:B,'расчеты_T&M'!C:C),0))),IF(ISERROR(SEARCH("ИП",IFERROR(_xlfn.XLOOKUP(A10,'расчеты_T&M'!B:B,'расчеты_T&M'!C:C),0))),IF(ISERROR(SEARCH("ГПХ",IFERROR(_xlfn.XLOOKUP(A10,'расчеты_T&M'!B:B,'расчеты_T&M'!C:C),0))),"","ГПХ"),"ИП"),"СМЗ"),"ЮЛ") | C10: =IF(B10="ГПХ",7.8%,0%) -> 0 | D10: =IFERROR(_xlfn.XLOOKUP(A10,Таблица1[Специалист],Таблица1[Ставка НДС]),0) -> 0 | E10: =IFERROR(_xlfn.XLOOKUP(A10,Таблица1[Специалист],Таблица1[Ставка Gross])/(1+IFERROR(_xlfn.XLOOKUP(A10,Таблица1[Специалист],Таблица1[Ставка НДС]),0)),0) -> 0 | F10: =SUMIFS(Таблица1[[Загрузка респлан]:[Загрузка респлан]],Таблица1[[Специалист]:[Специалист]],'шаблон расчета проекта'!$A10,Таблица1[[Месяц выполнения работ]:[Месяц выполнения работ]],'шаблон расчета проекта'!F$1) -> 0 | G10: =SUMIFS(Таблица1[[Загрузка респлан]:[Загрузка респлан]],Таблица1[[Специалист]:[Специалист]],'шаблон расчета проекта'!$A10,Таблица1[[Месяц выполнения работ]:[Месяц выполнения работ]],'шаблон расчета проекта'!G$1) -> 0 | H10: =SUMIFS(Таблица1[[Загрузка респлан]:[Загрузка респлан]],Таблица1[[Специалист]:[Специалист]],'шаблон расчета проекта'!$A10,Таблица1[[Месяц выполнения работ]:[Месяц выполнения работ]],'шаблон расчета проекта'!H$1) -> 0 | I10: =SUMIFS(Таблица1[[Загрузка респлан]:[Загрузка респлан]],Таблица1[[Специалист]:[Специалист]],'шаблон расчета проекта'!$A10,Таблица1[[Месяц выполнения работ]:[Месяц выполнения работ]],'шаблон расчета проекта'!I$1) -> 0 | J10: =SUMIFS(Таблица1[[Загрузка респлан]:[Загрузка респлан]],Таблица1[[Специалист]:[Специалист]],'шаблон расчета проекта'!$A10,Таблица1[[Месяц выполнения работ]:[Месяц выполнения работ]],'шаблон расчета проекта'!J$1) -> 0 | K10: =SUMIFS(Таблица1[[Загрузка респлан]:[Загрузка респлан]],Таблица1[[Специалист]:[Специалист]],'шаблон расчета проекта'!$A10,Таблица1[[Месяц выполнения работ]:[Месяц выполнения работ]],'шаблон расчета проекта'!K$1) -> 0 | L10: =SUMIFS(Таблица1[[Загрузка респлан]:[Загрузка респлан]],Таблица1[[Специалист]:[Специалист]],'шаблон расчета проекта'!$A10,Таблица1[[Месяц выполнения работ]:[Месяц выполнения работ]],'шаблон расчета проекта'!L$1) -> 0 | M10: =SUMIFS(Таблица1[[Загрузка респлан]:[Загрузка респлан]],Таблица1[[Специалист]:[Специалист]],'шаблон расчета проекта'!$A10,Таблица1[[Месяц выполнения работ]:[Месяц выполнения работ]],'шаблон расчета проекта'!M$1) -> 0 | ... BY10: =SUMIFS(Таблица1[[Загрузка респлан]:[Загрузка респлан]],Таблица1[[Специалист]:[Специалист]],'шаблон расчета проекта'!$A10,Таблица1[[Месяц выполнения работ]:[Месяц выполнения работ]],'шаблон расчета проекта'!BY$1) -> 0 | BZ10: =SUM(F10:BY10) -> 0
B11: =IF(ISERROR(SEARCH("ООО",IFERROR(_xlfn.XLOOKUP(A11,'расчеты_T&M'!B:B,'расчеты_T&M'!C:C),0))),IF(ISERROR(SEARCH("СМЗ",IFERROR(_xlfn.XLOOKUP(A11,'расчеты_T&M'!B:B,'расчеты_T&M'!C:C),0))),IF(ISERROR(SEARCH("ИП",IFERROR(_xlfn.XLOOKUP(A11,'расчеты_T&M'!B:B,'расчеты_T&M'!C:C),0))),IF(ISERROR(SEARCH("ГПХ",IFERROR(_xlfn.XLOOKUP(A11,'расчеты_T&M'!B:B,'расчеты_T&M'!C:C),0))),"","ГПХ"),"ИП"),"СМЗ"),"ЮЛ") | C11: =IF(B11="ГПХ",7.8%,0%) -> 0 | D11: =IFERROR(_xlfn.XLOOKUP(A11,Таблица1[Специалист],Таблица1[Ставка НДС]),0) -> 0 | E11: =IFERROR(_xlfn.XLOOKUP(A11,Таблица1[Специалист],Таблица1[Ставка Gross])/(1+IFERROR(_xlfn.XLOOKUP(A11,Таблица1[Специалист],Таблица1[Ставка НДС]),0)),0) -> 0 | F11: =SUMIFS(Таблица1[[Загрузка респлан]:[Загрузка респлан]],Таблица1[[Специалист]:[Специалист]],'шаблон расчета проекта'!$A11,Таблица1[[Месяц выполнения работ]:[Месяц выполнения работ]],'шаблон расчета проекта'!F$1) -> 0 | G11: =SUMIFS(Таблица1[[Загрузка респлан]:[Загрузка респлан]],Таблица1[[Специалист]:[Специалист]],'шаблон расчета проекта'!$A11,Таблица1[[Месяц выполнения работ]:[Месяц выполнения работ]],'шаблон расчета проекта'!G$1) -> 0 | H11: =SUMIFS(Таблица1[[Загрузка респлан]:[Загрузка респлан]],Таблица1[[Специалист]:[Специалист]],'шаблон расчета проекта'!$A11,Таблица1[[Месяц выполнения работ]:[Месяц выполнения работ]],'шаблон расчета проекта'!H$1) -> 0 | I11: =SUMIFS(Таблица1[[Загрузка респлан]:[Загрузка респлан]],Таблица1[[Специалист]:[Специалист]],'шаблон расчета проекта'!$A11,Таблица1[[Месяц выполнения работ]:[Месяц выполнения работ]],'шаблон расчета проекта'!I$1) -> 0 | J11: =SUMIFS(Таблица1[[Загрузка респлан]:[Загрузка респлан]],Таблица1[[Специалист]:[Специалист]],'шаблон расчета проекта'!$A11,Таблица1[[Месяц выполнения работ]:[Месяц выполнения работ]],'шаблон расчета проекта'!J$1) -> 0 | K11: =SUMIFS(Таблица1[[Загрузка респлан]:[Загрузка респлан]],Таблица1[[Специалист]:[Специалист]],'шаблон расчета проекта'!$A11,Таблица1[[Месяц выполнения работ]:[Месяц выполнения работ]],'шаблон расчета проекта'!K$1) -> 0 | L11: =SUMIFS(Таблица1[[Загрузка респлан]:[Загрузка респлан]],Таблица1[[Специалист]:[Специалист]],'шаблон расчета проекта'!$A11,Таблица1[[Месяц выполнения работ]:[Месяц выполнения работ]],'шаблон расчета проекта'!L$1) -> 0 | M11: =SUMIFS(Таблица1[[Загрузка респлан]:[Загрузка респлан]],Таблица1[[Специалист]:[Специалист]],'шаблон расчета проекта'!$A11,Таблица1[[Месяц выполнения работ]:[Месяц выполнения работ]],'шаблон расчета проекта'!M$1) -> 0 | ... BY11: =SUMIFS(Таблица1[[Загрузка респлан]:[Загрузка респлан]],Таблица1[[Специалист]:[Специалист]],'шаблон расчета проекта'!$A11,Таблица1[[Месяц выполнения работ]:[Месяц выполнения работ]],'шаблон расчета проекта'!BY$1) -> 0 | BZ11: =SUM(F11:BY11) -> 0
B12: =IF(ISERROR(SEARCH("ООО",IFERROR(_xlfn.XLOOKUP(A12,'расчеты_T&M'!B:B,'расчеты_T&M'!C:C),0))),IF(ISERROR(SEARCH("СМЗ",IFERROR(_xlfn.XLOOKUP(A12,'расчеты_T&M'!B:B,'расчеты_T&M'!C:C),0))),IF(ISERROR(SEARCH("ИП",IFERROR(_xlfn.XLOOKUP(A12,'расчеты_T&M'!B:B,'расчеты_T&M'!C:C),0))),IF(ISERROR(SEARCH("ГПХ",IFERROR(_xlfn.XLOOKUP(A12,'расчеты_T&M'!B:B,'расчеты_T&M'!C:C),0))),"","ГПХ"),"ИП"),"СМЗ"),"ЮЛ") | C12: =IF(B12="ГПХ",7.8%,0%) -> 0 | D12: =IFERROR(_xlfn.XLOOKUP(A12,Таблица1[Специалист],Таблица1[Ставка НДС]),0) -> 0 | E12: =IFERROR(_xlfn.XLOOKUP(A12,Таблица1[Специалист],Таблица1[Ставка Gross])/(1+IFERROR(_xlfn.XLOOKUP(A12,Таблица1[Специалист],Таблица1[Ставка НДС]),0)),0) -> 0 | F12: =SUMIFS(Таблица1[[Загрузка респлан]:[Загрузка респлан]],Таблица1[[Специалист]:[Специалист]],'шаблон расчета проекта'!$A12,Таблица1[[Месяц выполнения работ]:[Месяц выполнения работ]],'шаблон расчета проекта'!F$1) -> 0 | G12: =SUMIFS(Таблица1[[Загрузка респлан]:[Загрузка респлан]],Таблица1[[Специалист]:[Специалист]],'шаблон расчета проекта'!$A12,Таблица1[[Месяц выполнения работ]:[Месяц выполнения работ]],'шаблон расчета проекта'!G$1) -> 0 | H12: =SUMIFS(Таблица1[[Загрузка респлан]:[Загрузка респлан]],Таблица1[[Специалист]:[Специалист]],'шаблон расчета проекта'!$A12,Таблица1[[Месяц выполнения работ]:[Месяц выполнения работ]],'шаблон расчета проекта'!H$1) -> 0 | I12: =SUMIFS(Таблица1[[Загрузка респлан]:[Загрузка респлан]],Таблица1[[Специалист]:[Специалист]],'шаблон расчета проекта'!$A12,Таблица1[[Месяц выполнения работ]:[Месяц выполнения работ]],'шаблон расчета проекта'!I$1) -> 0 | J12: =SUMIFS(Таблица1[[Загрузка респлан]:[Загрузка респлан]],Таблица1[[Специалист]:[Специалист]],'шаблон расчета проекта'!$A12,Таблица1[[Месяц выполнения работ]:[Месяц выполнения работ]],'шаблон расчета проекта'!J$1) -> 0 | K12: =SUMIFS(Таблица1[[Загрузка респлан]:[Загрузка респлан]],Таблица1[[Специалист]:[Специалист]],'шаблон расчета проекта'!$A12,Таблица1[[Месяц выполнения работ]:[Месяц выполнения работ]],'шаблон расчета проекта'!K$1) -> 0 | L12: =SUMIFS(Таблица1[[Загрузка респлан]:[Загрузка респлан]],Таблица1[[Специалист]:[Специалист]],'шаблон расчета проекта'!$A12,Таблица1[[Месяц выполнения работ]:[Месяц выполнения работ]],'шаблон расчета проекта'!L$1) -> 0 | M12: =SUMIFS(Таблица1[[Загрузка респлан]:[Загрузка респлан]],Таблица1[[Специалист]:[Специалист]],'шаблон расчета проекта'!$A12,Таблица1[[Месяц выполнения работ]:[Месяц выполнения работ]],'шаблон расчета проекта'!M$1) -> 0 | ... BY12: =SUMIFS(Таблица1[[Загрузка респлан]:[Загрузка респлан]],Таблица1[[Специалист]:[Специалист]],'шаблон расчета проекта'!$A12,Таблица1[[Месяц выполнения работ]:[Месяц выполнения работ]],'шаблон расчета проекта'!BY$1) -> 0 | BZ12: =SUM(F12:BY12) -> 0
B13: =IF(ISERROR(SEARCH("ООО",IFERROR(_xlfn.XLOOKUP(A13,'расчеты_T&M'!B:B,'расчеты_T&M'!C:C),0))),IF(ISERROR(SEARCH("СМЗ",IFERROR(_xlfn.XLOOKUP(A13,'расчеты_T&M'!B:B,'расчеты_T&M'!C:C),0))),IF(ISERROR(SEARCH("ИП",IFERROR(_xlfn.XLOOKUP(A13,'расчеты_T&M'!B:B,'расчеты_T&M'!C:C),0))),IF(ISERROR(SEARCH("ГПХ",IFERROR(_xlfn.XLOOKUP(A13,'расчеты_T&M'!B:B,'расчеты_T&M'!C:C),0))),"","ГПХ"),"ИП"),"СМЗ"),"ЮЛ") | C13: =IF(B13="ГПХ",7.8%,0%) -> 0 | D13: =IFERROR(_xlfn.XLOOKUP(A13,Таблица1[Специалист],Таблица1[Ставка НДС]),0) -> 0 | E13: =IFERROR(_xlfn.XLOOKUP(A13,Таблица1[Специалист],Таблица1[Ставка Gross])/(1+IFERROR(_xlfn.XLOOKUP(A13,Таблица1[Специалист],Таблица1[Ставка НДС]),0)),0) -> 0 | F13: =SUMIFS(Таблица1[[Загрузка респлан]:[Загрузка респлан]],Таблица1[[Специалист]:[Специалист]],'шаблон расчета проекта'!$A13,Таблица1[[Месяц выполнения работ]:[Месяц выполнения работ]],'шаблон расчета проекта'!F$1) -> 0 | G13: =SUMIFS(Таблица1[[Загрузка респлан]:[Загрузка респлан]],Таблица1[[Специалист]:[Специалист]],'шаблон расчета проекта'!$A13,Таблица1[[Месяц выполнения работ]:[Месяц выполнения работ]],'шаблон расчета проекта'!G$1) -> 0 | H13: =SUMIFS(Таблица1[[Загрузка респлан]:[Загрузка респлан]],Таблица1[[Специалист]:[Специалист]],'шаблон расчета проекта'!$A13,Таблица1[[Месяц выполнения работ]:[Месяц выполнения работ]],'шаблон расчета проекта'!H$1) -> 0 | I13: =SUMIFS(Таблица1[[Загрузка респлан]:[Загрузка респлан]],Таблица1[[Специалист]:[Специалист]],'шаблон расчета проекта'!$A13,Таблица1[[Месяц выполнения работ]:[Месяц выполнения работ]],'шаблон расчета проекта'!I$1) -> 0 | J13: =SUMIFS(Таблица1[[Загрузка респлан]:[Загрузка респлан]],Таблица1[[Специалист]:[Специалист]],'шаблон расчета проекта'!$A13,Таблица1[[Месяц выполнения работ]:[Месяц выполнения работ]],'шаблон расчета проекта'!J$1) -> 0 | K13: =SUMIFS(Таблица1[[Загрузка респлан]:[Загрузка респлан]],Таблица1[[Специалист]:[Специалист]],'шаблон расчета проекта'!$A13,Таблица1[[Месяц выполнения работ]:[Месяц выполнения работ]],'шаблон расчета проекта'!K$1) -> 0 | L13: =SUMIFS(Таблица1[[Загрузка респлан]:[Загрузка респлан]],Таблица1[[Специалист]:[Специалист]],'шаблон расчета проекта'!$A13,Таблица1[[Месяц выполнения работ]:[Месяц выполнения работ]],'шаблон расчета проекта'!L$1) -> 0 | M13: =SUMIFS(Таблица1[[Загрузка респлан]:[Загрузка респлан]],Таблица1[[Специалист]:[Специалист]],'шаблон расчета проекта'!$A13,Таблица1[[Месяц выполнения работ]:[Месяц выполнения работ]],'шаблон расчета проекта'!M$1) -> 0 | ... BY13: =SUMIFS(Таблица1[[Загрузка респлан]:[Загрузка респлан]],Таблица1[[Специалист]:[Специалист]],'шаблон расчета проекта'!$A13,Таблица1[[Месяц выполнения работ]:[Месяц выполнения работ]],'шаблон расчета проекта'!BY$1) -> 0 | BZ13: =SUM(F13:BY13) -> 0
